Traceback (most recent call last):
  File "/usr/local/Cellar/pytho::1 - - [30/Oct/2025 00:23:56] "GET /welcome.html HTTP/1.1" 200 -
n3.10/runpy.py", line 196, in _run_module_as_main
    return _run_code(code, main_globals, None,
  File "/usr/local/Cellar/python@3.10/3.10.10/Frameworks/Python.framework/Versions/3.10/lib/python3.10/runpy.py", line 86, in _run_code
    exec(code, run_globals)
  File "/usr/local/Cellar/python@3.10/3.10.10/Frameworks/Python.framework/Versions/3.10/lib/python3.10/http/server.py", line 1307, in <module>
    test(
  File "/usr/local/Cellar/python@3.10/3.10.10/Frameworks/Python.framework/Versions/3.10/lib/python3.10/http/server.py", line 1258, in test
    with ServerClass(addr, HandlerClass) as httpd:
  File "/usr/local/Cellar/python@3.10/3.10.10/Frameworks/Python.framework/Versions/3.10/lib/python3.10/socketserver.py", line 452, in __init__
    self.server_bind()
  File "/usr/local/Cellar/python@3.10/3.10.10/Frameworks/Python.framework/Versions/3.10/lib/python3.10/http/server.py", line 1301, in server_bind
    return super().server_bind()
  File "/usr/local/Cellar/python@3.10/3.10.10/Frameworks/Python.framework/Versions/3.10/lib/python3.10/http/server.py", line 137, in server_bind
    socketserver.TCPServer.server_bind(self)
  File "/usr/local/Cellar/python@3.10/3.10.10/Frameworks/Python.framework/Versions/3.10/lib/python3.10/socketserver.py", line 466, in server_bind
    self.socket.bind(self.server_address)
OSError: [Errno 48] Address already in use
